Workbook

Sheet 中国
A1: 指标名称 | B1: 指标类型 | C1: 国家 | D1: 频率 | E1: 数据代码 | F1: 单位
A2: CPI（整体）当月同比 | B2: CPI | C2: 中国 | D2: 月度 | E2: M0000612 | F2: %
A3: M0 | B3: 货币供应 | C3: 中国 | D3: 月度 | E3: M0001380 | F3: 亿元
A4: M1 | B4: 货币供应 | C4: 中国 | D4: 月度 | E4: M0001382 | F4: 亿元
A5: M2 | B5: 货币供应 | C5: 中国 | D5: 月度 | E5: M0001384 | F5: 亿元
A6: 国债收益率（1年） | B6: 国债收益率 | C6: 中国 | D6: 日度 | E6: M1006387 | F6: %
A7: 国债收益率（3年） | B7: 国债收益率 | C7: 中国 | D7: 日度 | E7: M1006388 | F7: %
A8: 国债收益率（5年） | B8: 国债收益率 | C8: 中国 | D8: 日度 | E8: M1006389 | F8: %
A9: 国债收益率（7年） | B9: 国债收益率 | C9: 中国 | D9: 日度 | E9: M1006390 | F9: %
A10: 国债收益率（10年） | B10: 国债收益率 | C10: 中国 | D10: 日度 | E10: M1006391 | F10: %
A11: 人民币存款准备金率：中小型存款类金融机构 | B11: 存款准备金率 | C11: 中国 | D11: 月度 | E11: M0043821 | F11: %
A12: 人民币存款准备金率：大型存款类金融机构 | B12: 存款准备金率 | C12: 中国 | D12: 月度 | E12: M0061518 | F12: %
A13: 即期汇率（美元兑人民币） | B13: 汇率 | C13: 中国, 美国 | D13: 日度 | E13: USDCNY.FX
A14: 即期汇率（美元兑港元） | B14: 汇率 | C14: 美国, 中国 | D14: 日度 | E14: USDHKD.FX
A15: 沪深300 | B15: 股票市场指数 | C15: 中国 | D15: 日度 | E15: 000300.SH
A16: CZCE 动力煤（主连） | B16: 大宗商品 | C16: 中国 | D16: 日度 | E16: ZC.CZC
A17: CZCE 棉花（主连） | B17: 大宗商品 | C17: 中国 | D17: 日度 | E17: CF.CZC
A18: DCE 焦炭（主连） | B18: 大宗商品 | C18: 中国 | D18: 日度 | E18: J.DCE
A19: DCE 焦煤（主连） | B19: 大宗商品 | C19: 中国 | D19: 日度 | E19: JM.DCE
A20: DCE 铁矿石（主连） | B20: 大宗商品 | C20: 中国 | D20: 日度 | E20: I.DCE
A21: DCE LPG（主连） | B21: 大宗商品 | C21: 中国 | D21: 日度 | E21: PG.DCE
A22: INE 原油（主连） | B22: 大宗商品 | C22: 中国 | D22: 日度 | E22: SC.INE
A23: SHFE 不锈钢（主连） | B23: 大宗商品 | C23: 中国 | D23: 日度 | E23: SS.SHF
A24: SHFE 铜（主连） | B24: 大宗商品 | C24: 中国 | D24: 日度 | E24: CU.SHF
... A67: CZCE 纯碱（主连） | B67: 大宗商品 | C67: 中国 | D67: 日度 | E67: SA.CZC
A68: ShiborON利率互换收盘曲线（即期）：1D | B68: 货币市场金融工具 | C68: 中国 | D68: 日度 | E68: M1016185 | F68: %
A69: ShiborON利率互换收盘曲线（即期）：1M | B69: 货币市场金融工具 | C69: 中国 | D69: 日度 | E69: M1016186 | F69: %
A70: ShiborON利率互换收盘曲线（即期）：3M | B70: 货币市场金融工具 | C70: 中国 | D70: 日度 | E70: M1016187 | F70: %
A71: ShiborON利率互换收盘曲线（即期）：6M | B71: 货币市场金融工具 | C71: 中国 | D71: 日度 | E71: M1016188 | F71: %
A72: ShiborON利率互换收盘曲线（即期）：1Y | B72: 货币市场金融工具 | C72: 中国 | D72: 日度 | E72: M1016190 | F72: %
A73: 银行间国债即期收益率：6个月 | B73: 货币市场金融工具 | C73: 中国 | D73: 日度 | E73: M1000081 | F73: %
A74: 银行间国债即期收益率：1年 | B74: 货币市场金融工具 | C74: 中国 | D74: 日度 | E74: M1000082 | F74: %
A75: 银行间国债即期收益率：2年 | B75: 货币市场金融工具 | C75: 中国 | D75: 日度 | E75: M1000083 | F75: %
A76: 银行间国债即期收益率：3年 | B76: 货币市场金融工具 | C76: 中国 | D76: 日度 | E76: M1000084 | F76: %
A77: 银行间国债即期收益率：5年 | B77: 货币市场金融工具 | C77: 中国 | D77: 日度 | E77: M1000085 | F77: %
A78: 银行间国债即期收益率：10年 | B78: 货币市场金融工具 | C78: 中国 | D78: 日度 | E78: M1000086 | F78: %
A79: 超短期融资券到期收益率（AAA）：0.1年 | B79: 货币市场金融工具 | C79: 中国 | D79: 日度 | E79: M1008445 | F79: %
... A84: 短期贷款利率（6个月以下） | B84: 货币市场金融工具 | C84: 中国 | D84: 月度 | E84: M0043814 | F84: %
A85: 波罗的海干散货指数 | B85: 货运价格 | C85: 全球 | D85: 日度 | E85: BADI.GI
A86: 天津航运指数 | B86: 货运价格 | C86: 中国, 全球 | D86: 日度 | E86: S6402901
...

Sheet 美国
A1: 指标名称 | B1: 指标类型 | C1: 国家 | D1: 频率 | E1: 数据代码 | F1: 单位
A2: 即期汇率（美元兑人民币） | B2: 汇率 | C2: 中国, 美国 | D2: 日度 | E2: USDCNY.FX
A3: 即期汇率（欧元兑美元） | B3: 汇率 | C3: 欧洲, 美国 | D3: 日度 | E3: EURUSE.FX
A4: 即期汇率（美元兑港元） | B4: 汇率 | C4: 美国, 中国 | D4: 日度 | E4: USDHKD.FX
A5: 即期汇率（美元兑日元） | B5: 汇率 | C5: 日本, 美国 | D5: 日度 | E5: USDJPY.FX
A6: 即期汇率（英镑对美元） | B6: 汇率 | C6: 英国, 美国 | D6: 日度 | E6: GBPUSD.FX
A7: 即期汇率（美元兑卢布） | B7: 汇率 | C7: 俄罗斯, 美国 | D7: 日度 | E7: USDRUB.FX
A8: 即期汇率（澳元兑美元） | B8: 汇率 | C8: 澳大利亚, 美国 | D8: 日度 | E8: AUDUSD.FX
A9: 即期汇率（美元兑加元） | B9: 汇率 | C9: 加拿大, 美国 | D9: 日度 | E9: USDCAD.FX
A10: 波罗的海干散货指数 | B10: 货运价格 | C10: 全球 | D10: 日度 | E10: BADI.GI
A11: 天津航运指数 | B11: 货运价格 | C11: 中国, 全球 | D11: 日度 | E11: S6402901
A12: 美国CPI（整体）当月同比 | B12: CPI | C12: 美国 | D12: 月度 | E12: G0000027 | F12: %
A13: 美国M1 | B13: 货币供应 | C13: 美国 | D13: 月度 | E13: G0003384 | F13: 十亿美元
A14: 美国M2 | B14: 货币供应 | C14: 美国 | D14: 月度 | E14: G0003385 | F14: 十亿美元
A15: 美国：国债收益率：1年 | B15: 国债收益率 | C15: 美国 | D15: 日度 | E15: G0000886 | F15: %
A16: 美国：国债收益率：3年 | B16: 国债收益率 | C16: 美国 | D16: 日度 | E16: G0000888 | F16: %
A17: 美国：国债收益率：5年 | B17: 国债收益率 | C17: 美国 | D17: 日度 | E17: G0000889 | F17: %
A18: 美国：国债收益率：7年 | B18: 国债收益率 | C18: 美国 | D18: 日度 | E18: G0000890 | F18: %
A19: 美国：国债收益率：10年 | B19: 国债收益率 | C19: 美国 | D19: 日度 | E19: G0000891 | F19: %
A20: 美国：存款准备金率 | B20: 存款准备金率 | C20: 美国 | D20: 日度 | E20: G1167030 | F20: %
A21: 美国：超额存款准备金率 | B21: 存款准备金率 | C21: 美国 | D21: 日度 | E21: G1167029 | F21: %
A22: 标普500 | B22: 股票市场指数 | C22: 美国 | D22: 日度 | E22: SPX.GI
A23: 纳斯达克指数 | B23: 股票市场指数 | C23: 美国 | D23: 日度 | E23: IXIC.GI
A24: 道琼斯工业指数 | B24: 股票市场指数 | C24: 美国 | D24: 日度 | E24: DJI.GI
A25: 罗素2000指数 | B25: 股票市场指数 | C25: 美国 | D25: 日度 | E25: RTY.GI
A26: CME活牛 | B26: 大宗商品 | C26: 美国 | D26: 日度 | E26: LC.CME
A27: CME饲牛 | B27: 大宗商品 | C27: 美国 | D27: 日度 | E27: FC.CME
A28: CME瘦肉猪 | B28: 大宗商品 | C28: 美国 | D28: 日度 | E28: LH.CME
A29: CME三级牛奶 | B29: 大宗商品 | C29: 美国 | D29: 日度 | E29: DA.CME
A30: CBOT大豆 | B30: 大宗商品 | C30: 美国 | D30: 日度 | E30: S.CBT
A31: CBOT玉米 | B31: 大宗商品 | C31: 美国 | D31: 日度 | E31: C.CBT
A32: CBOT小麦 | B32: 大宗商品 | C32: 美国 | D32: 日度 | E32: W.CBT
A33: CBOT燕麦 | B33: 大宗商品 | C33: 美国 | D33: 日度 | E33: O.CBT
... A50: COMEX钢卷 | B50: 大宗商品 | C50: 美国 | D50: 日度 | E50: HRC.CMX
A51: LIBOR：美元：隔夜 | B51: 货币市场金融工具 | C51: 美国 | D51: 日度 | E51: G0000894 | F51: %
A52: LIBOR：美元：1周 | B52: 货币市场金融工具 | C52: 美国 | D52: 日度 | E52: G0000895 | F52: %
A53: LIBOR：美元：1个月 | B53: 货币市场金融工具 | C53: 美国 | D53: 日度 | E53: G0000897 | F53: %
A54: LIBOR：美元：3个月 | B54: 货币市场金融工具 | C54: 美国 | D54: 日度 | E54: G0000898 | F54: %
A55: LIBOR：美元：6个月 | B55: 货币市场金融工具 | C55: 美国 | D55: 日度 | E55: G0000899 | F55: %
A56: LIBOR：美元：12个月 | B56: 货币市场金融工具 | C56: 美国 | D56: 日度 | E56: G0000901 | F56: %
...

Sheet 欧洲
A1: 指标名称 | B1: 指标类型 | C1: 国家 | D1: 频率 | E1: 数据代码 | F1: 单位
A2: 即期汇率（欧元兑美元） | B2: 汇率 | C2: 欧洲, 美国 | D2: 日度 | E2: EURUSE.FX
A3: 即期汇率（英镑对美元） | B3: 汇率 | C3: 英国, 美国 | D3: 日度 | E3: GBPUSD.FX
A4: 波罗的海干散货指数 | B4: 货运价格 | C4: 全球 | D4: 日度 | E4: BADI.GI
A5: 天津航运指数 | B5: 货运价格 | C5: 中国, 全球 | D5: 日度 | E5: S6402901
A6: 欧元区：M1 | B6: 货币供应 | C6: 欧洲 | D6: 月度 | E6: G1000105 | F6: 百万欧元
A7: 欧元区：M2 | B7: 货币供应 | C7: 欧洲 | D7: 月度 | E7: G1000106 | F7: 百万欧元
A8: 欧元区：M3 | B8: 货币供应 | C8: 欧洲 | D8: 月度 | E8: G1000104 | F8: 百万欧元
A9: 欧元区：HICP（调和CPI）：当月同比 | B9: CPI | C9: 欧洲 | D9: 月度 | E9: G0001698 | F9: %
A10: 欧元区：公债收益率：3个月 | B10: 国债收益率 | C10: 欧洲 | D10: 日度 | E10: G0003948 | F10: %
A11: 欧元区：公债收益率：6个月 | B11: 国债收益率 | C11: 欧洲 | D11: 日度 | E11: G0003949 | F11: %
A12: 欧元区：公债收益率：9个月 | B12: 国债收益率 | C12: 欧洲 | D12: 日度 | E12: G0003950 | F12: %
A13: 欧元区：公债收益率：1年 | B13: 国债收益率 | C13: 欧洲 | D13: 日度 | E13: G0003951 | F13: %
A14: 欧元区：公债收益率：3年 | B14: 国债收益率 | C14: 欧洲 | D14: 日度 | E14: G0003953 | F14: %
A15: 欧元区：公债收益率：5年 | B15: 国债收益率 | C15: 欧洲 | D15: 日度 | E15: G0003954 | F15: %
A16: 欧元区：公债收益率：7年 | B16: 国债收益率 | C16: 欧洲 | D16: 日度 | E16: G0003955 | F16: %
A17: 欧元区：公债收益率：10年 | B17: 国债收益率 | C17: 欧洲 | D17: 日度 | E17: G0003956 | F17: %
... A29: 欧元区：准备金要求 | B29: 存款准备金率 | C29: 欧洲 | D29: 日度 | E29: G0926430 | F29: 百万欧元
A30: 德国DAX指数 | B30: 股票市场指数 | C30: 欧洲 | D30: 日度 | E30: GDAXI.GI
A31: 法国CAC40指数 | B31: 股票市场指数 | C31: 欧洲 | D31: 日度 | E31: FCHI.GI
A32: 英国富时100指数 | B32: 股票市场指数 | C32: 欧洲 | D32: 日度 | E32: FTSE.GI
A33: ICE布油 | B33: 大宗商品 | C33: 欧洲 | D33: 日度 | E33: B.IPE
A34: ICE WTI原油 | B34: 大宗商品 | C34: 欧洲 | D34: 日度 | E34: T.IPE
A35: ICE取暖油 | B35: 大宗商品 | C35: 欧洲 | D35: 日度 | E35: O.IPE
A36: ICE柴油 | B36: 大宗商品 | C36: 欧洲 | D36: 日度 | E36: G.IPE
A37: ICE NYH(RBOB)汽油 | B37: 大宗商品 | C37: 欧洲 | D37: 日度 | E37: N.IPE
A38: LME 铜 | B38: 大宗商品 | C38: 欧洲 | D38: 日度 | E38: CA.LME
A39: LME 铝 | B39: 大宗商品 | C39: 欧洲 | D39: 日度 | E39: AH.LME
A40: LME 锌 | B40: 大宗商品 | C40: 欧洲 | D40: 日度 | E40: ZS.LME
A41: LME 铅 | B41: 大宗商品 | C41: 欧洲 | D41: 日度 | E41: PB.LME
... A46: 欧盟27国：消费者信心指数：季调 | B46: 居民收入 | C46: 欧洲 | D46: 月度 | E46: G0926396

Sheet 日本
A1: 指标名称 | B1: 指标类型 | C1: 国家 | D1: 频率 | E1: 数据代码 | F1: 单位
A2: 即期汇率（美元兑日元） | B2: 汇率 | C2: 日本, 美国 | D2: 日度 | E2: USDJPY.FX
A3: 波罗的海干散货指数 | B3: 货运价格 | C3: 全球 | D3: 日度 | E3: BADI.GI
A4: 天津航运指数 | B4: 货运价格 | C4: 中国, 全球 | D4: 日度 | E4: S6402901
A5: 日本：货币供应量：平均余额：M1 | B5: 货币供应 | C5: 日本 | D5: 月度 | E5: G0900089 | F5: 万亿日元
A6: 日本：货币供应量：平均余额：M2 | B6: 货币供应 | C6: 日本 | D6: 月度 | E6: G0900087 | F6: 万亿日元
A7: 日本：货币供应量：平均余额：M3 | B7: 货币供应 | C7: 日本 | D7: 月度 | E7: G0900088 | F7: 万亿日元
A8: 日本：基础货币：平均余额：季调 | B8: 货币供应 | C8: 日本 | D8: 月度 | E8: G0900062 | F8: 亿日元
A9: 日本：准备金余额：实值 | B9: 货币供应 | C9: 日本 | D9: 月度 | E9: G0900061 | F9: 亿日元
A10: 日本：日元TIBOR：1周 | B10: 货币市场金融工具 | C10: 日本 | D10: 日度 | E10: G1241481 | F10: %
A11: 日本：日元TIBOR：1个月 | B11: 货币市场金融工具 | C11: 日本 | D11: 日度 | E11: G1241482 | F11: %
A12: 日本：日元TIBOR：2个月 | B12: 货币市场金融工具 | C12: 日本 | D12: 日度 | E12: G1241483 | F12: %
A13: 日本：日元TIBOR：3个月 | B13: 货币市场金融工具 | C13: 日本 | D13: 日度 | E13: G1241484 | F13: %
A14: 日本：日元TIBOR：6个月 | B14: 货币市场金融工具 | C14: 日本 | D14: 日度 | E14: G1241487 | F14: %
A15: 日本：日元TIBOR：12个月 | B15: 货币市场金融工具 | C15: 日本 | D15: 日度 | E15: G1241493 | F15: %
A16: 日本：企业债收益率指数：综合 | B16: 货币市场金融工具 | C16: 日本 | D16: 日度 | E16: G1241528 | F16: 1996年12月31日=100
... A23: 日本：CPI：当月同比 | B23: CPI | C23: 日本 | D23: 月度 | E23: G1254021 | F23: %
A24: 日经225指数 | B24: 股票市场指数 | C24: 日本 | D24: 日度 | E24: N225.GI
A25: TCE 3号烟片胶 | B25: 大宗商品 | C25: 日本 | D25: 日度 | E25: RSS3.TCE
A26: TCE 黄金 | B26: 大宗商品 | C26: 日本 | D26: 日度 | E26: GOLD.TCE
A27: TCE 铂 | B27: 大宗商品 | C27: 日本 | D27: 日度 | E27: PLAT000.TCE
A28: 日本：消费者信心指数 | B28: 居民收入 | C28: 日本 | D28: 月度 | E28: G0001054

Sheet 中国汇率&amp;amp;期货（数据表）
B1: 收盘价
B2: close
A3: 日期 | B3: =[1]!s_info_name(B4) | C3: =[1]!s_info_name(C4) | D3: =[1]!s_info_name(D4) | E3: =[1]!s_info_name(E4) | F3: =[1]!s_info_name(F4) | G3: =[1]!s_info_name(G4) | H3: =[1]!s_info_name(H4) | I3: =[1]!s_info_name(I4) | ... BE3: =[1]!s_info_name(BE4)
A4: Date | B4: USDCNY.FX | C4: USDHKD.FX | D4: 000300.SH | E4: ZC.CZC | F4: CF.CZC | G4: J.DCE | H4: JM.DCE | I4: I.DCE | J4: PG.DCE | K4: SC.INE | L4: SS.SHF | M4: CU.SHF | N4: AL.SHF | O4: ZN.SHF | P4: PB.SHF | Q4: NI.SHF | R4: SN.SHF | S4: AU.SHF | T4: AG.SHF | U4: RB.SHF | V4: WR.SHF | W4: HC.SHF | X4: FU.SHF | Y4: BU.SHF | Z4: RU.SHF | AA4: SP.SHF | AB4: M.DCE | AC4: Y.DCE | AD4: A.DCE | AE4: B.DCE | AF4: P.DCE | AG4: C.DCE | AH4: CS.DCE | AI4: LH.DCE | AJ4: JD.DCE | AK4: L.DCE | AL4: V.DCE | AM4: PP.DCE | AN4: EG.DCE | AO4: RR.DCE | AP4: EB.DCE | AQ4: SR.CZC | AR4: FG.CZC | AS4: TA.CZC | AT4: PF.CZC | AU4: MA.CZC | AV4: OI.CZC | AW4: RM.CZC | AX4: PK.CZC | AY4: SF.CZC | AZ4: SM.CZC | BA4: AP.CZC | BB4: CJ.CZC | BC4: UR.CZC | BD4: SA.CZC | BE4: BADI.GI
A5: 44665 | B5: =[1]!WSD(B4:BE4,B2,"-100D","","Days=Weekdays","TradingCalendar=SSE","Fill=Previous","PriceAdj=F","Sort=D","rptType=1","ShowParams=Y","cols=56;rows=73") | C5: 7.8397 | D5: 4191.5684 | E5: 813 | F5: 21550 | G5: 4234.5 | H5: 3242 | I5: 901.5 | J5: 6152 | K5: 666 | L5: 19830 | M5: 74180 | N5: 21440 | O5: 27845 | P5: 15320 | Q5: 223880 | R5: 339240 | S5: 404.32 | T5: 5251 | U5: 5004 | V5: 5499 | W5: 5160 | X5: 4047 | Y5: 3834 | Z5: 13460 | AA5: 7022 | AB5: 3928 | AC5: 10818 | AD5: 6191 | AE5: 5135 | AF5: 10918 | AG5: 2949 | AH5: 3329 | AI5: 12695 | AJ5: 4808 | AK5: 8892 | AL5: 9141 | AM5: 8721 | AN5: 4814 | AO5: 3348 | AP5: 9726 | AQ5: 6040 | AR5: 2020 | AS5: 6062 | AT5: 7786 | AU5: 2871 | AV5: 13132 | AW5: 3771 | AX5: 9414 | AY5: 10462 | AZ5: 8686 | BA5: 8808 | BB5: 11340 | BC5: 2708 | BD5: 3138 | BE5: 2068
A6: 44664 | B6: 6.3682 | C6: 7.8397 | D6: 4139.737 | E6: 805 | F6: 21515 | G6: 4088.5 | H6: 3196 | I6: 884 | J6: 5946 | K6: 650.5 | L6: 19805 | M6: 74030 | N6: 21270 | O6: 28395 | P6: 15490 | Q6: 221050 | R6: 333180 | S6: 403.7 | T6: 5208 | U6: 4915 | V6: 5409 | W6: 5086 | X6: 3983 | Y6: 3858 | Z6: 13345 | AA6: 6986 | AB6: 3905 | AC6: 10664 | AD6: 6209 | AE6: 5073 | AF6: 10622 | AG6: 2917 | AH6: 3297 | AI6: 12750 | AJ6: 4791 | AK6: 8836 | AL6: 9117 | AM6: 8662 | AN6: 4782 | AO6: 3344 | AP6: 9684 | AQ6: 6020 | AR6: 2019 | AS6: 6062 | AT6: 7742 | AU6: 2861 | AV6: 12915 | AW6: 3687 | AX6: 9454 | AY6: 10342 | AZ6: 8610 | BA6: 8812 | BB6: 11260 | BC6: 2697 | BD6: 3081 | BE6: 2068
A7: 44663 | B7: 6.3621 | C7: 7.8375 | D7: 4179.9727 | E7: 808.4 | F7: 21630 | G7: 4148 | H7: 3231 | I7: 925 | J7: 5924 | K7: 635.4 | L7: 19555 | M7: 73350 | N7: 21070 | O7: 27870 | P7: 15370 | Q7: 212620 | R7: 339830 | S7: 401.78 | T7: 5179 | U7: 5035 | V7: 5438 | W7: 5180 | X7: 3862 | Y7: 3775 | Z7: 13545 | AA7: 7030 | AB7: 3923 | AC7: 10708 | AD7: 6207 | AE7: 5084 | AF7: 10638 | AG7: 2919 | AH7: 3305 | AI7: 12695 | AJ7: 4814 | AK7: 8932 | AL7: 9242 | AM7: 8751 | AN7: 4896 | AO7: 3331 | AP7: 9870 | AQ7: 6048 | AR7: 2075 | AS7: 6128 | AT7: 7804 | AU7: 2840 | AV7: 12878 | AW7: 3735 | AX7: 9480 | AY7: 10398 | AZ7: 8644 | BA7: 9097 | BB7: 11495 | BC7: 2647 | BD7: 3099 | BE7: 2035
A8: 44662 | B8: 6.3665 | C8: 7.838 | D8: 4100.0703 | E8: 805 | F8: 21555 | G8: 3929.5 | H8: 3106 | I8: 868.5 | J8: 5804 | K8: 624.6 | L8: 19330 | M8: 73230 | N8: 21005 | O8: 27240 | P8: 15385 | Q8: 210900 | R8: 337360 | S8: 399.6 | T8: 5083 | U8: 4867 | V8: 5267 | W8: 5038 | X8: 3770 | Y8: 3712 | Z8: 13540 | AA8: 7050 | AB8: 3939 | AC8: 10482 | AD8: 6280 | AE8: 5048 | AF8: 10302 | AG8: 2914 | AH8: 3299 | AI8: 12525 | AJ8: 4860 | AK8: 8877 | AL8: 9064 | AM8: 8594 | AN8: 4825 | AO8: 3332 | AP8: 9760 | AQ8: 6017 | AR8: 2027 | AS8: 5920 | AT8: 7566 | AU8: 2799 | AV8: 12529 | AW8: 3765 | AX8: 9456 | AY8: 10230 | AZ8: 8594 | BA8: 9115 | BB8: 11250 | BC8: 2622 | BD8: 2947 | BE8: 2031
A9: 44659 | B9: 6.3615 | C9: 7.8393 | D9: 4230.7669 | E9: 803.2 | F9: 21605 | G9: 4059 | H9: 3214 | I9: 918.5 | J9: 5694 | K9: 625.6 | L9: 20025 | M9: 73760 | N9: 21825 | O9: 27150 | P9: 15455 | Q9: 218170 | R9: 340770 | S9: 396.04 | T9: 5030 | U9: 5019 | V9: 5438 | W9: 5195 | X9: 3791 | Y9: 3745 | Z9: 13545 | AA9: 6890 | AB9: 3880 | AC9: 10496 | AD9: 6271 | AE9: 4978 | AF9: 10362 | AG9: 2924 | AH9: 3326 | AI9: 12675 | AJ9: 4913 | AK9: 8980 | AL9: 9166 | AM9: 8746 | AN9: 5048 | AO9: 3359 | AP9: 10038 | AQ9: 5927 | AR9: 2040 | AS9: 6040 | AT9: 7682 | AU9: 2867 | AV9: 12630 | AW9: 3745 | AX9: 9390 | AY9: 10770 | AZ9: 8810 | BA9: 8931 | BB9: 11630 | BC9: 2612 | BD9: 2944 | BE9: 2055
A10: 44658 | B10: 6.3569 | C10: 7.8378 | D10: 4209.0998 | E10: 802 | F10: 21575 | G10: 4050 | H10: 3200 | I10: 900 | J10: 5821 | K10: 628.7 | L10: 20365 | M10: 73410 | N10: 21815 | O10: 27280 | P10: 15675 | Q10: 213330 | R10: 340490 | S10: 394.94 | T10: 4961 | U10: 5070 | V10: 5478 | W10: 5228 | X10: 3751 | Y10: 3818 | Z10: 13555 | AA10: 6776 | AB10: 3829 | AC10: 10322 | AD10: 6184 | AE10: 4903 | AF10: 10180 | AG10: 2951 | AH10: 3371 | AI10: 12775 | AJ10: 4893 | AK10: 9048 | AL10: 9252 | AM10: 8790 | AN10: 5064 | AO10: 3368 | AP10: 9958 | AQ10: 5863 | AR10: 2014 | AS10: 6070 | AT10: 7760 | AU10: 2936 | AV10: 12748 | AW10: 3709 | AX10: 9374 | AY10: 10430 | AZ10: 8620 | BA10: 8667 | BB10: 11040 | BC10: 2700 | BD10: 2916 | BE10: 2061
A11: 44657 | B11: 6.3593 | C11: 7.8382 | D11: 4263.8411 | E11: 806.4 | F11: 21675 | G11: 4074.5 | H11: 3240.5 | I11: 926.5 | J11: 5948 | K11: 677.1 | L11: 20830 | M11: 73720 | N11: 22540 | O11: 27375 | P11: 15770 | Q11: 223300 | R11: 346020 | S11: 394.5 | T11: 4980 | U11: 5121 | V11: 5571 | W11: 5268 | X11: 3936 | Y11: 3998 | Z11: 13845 | AA11: 7014 | AB11: 3856 | AC11: 10370 | AD11: 6278 | AE11: 4930 | AF11: 11646 | AG11: 2869 | AH11: 3387 | AI11: 12745 | AJ11: 4398 | AK11: 9067 | AL11: 9282 | AM11: 8810 | AN11: 5063 | AO11: 3364 | AP11: 9958 | AQ11: 5876 | AR11: 2039 | AS11: 6168 | AT11: 7812 | AU11: 2959 | AV11: 12936 | AW11: 3660 | AX11: 9352 | AY11: 10408 | AZ11: 8870 | BA11: 8884 | BB11: 11480 | BC11: 2755 | BD11: 2941 | BE11: 2128
A12: 44656 | B12: 6.3633 | C12: 7.835 | D12: 4276.158 | E12: 809.2 | F12: 21740 | G12: 3997 | H12: 3244 | I12: 926 | J12: 5876 | K12: 648.7 | L12: 20280 | M12: 73160 | N12: 22640 | O12: 26875 | P12: 15740 | Q12: 217910 | R12: 340950 | S12: 396.26 | T12: 5038 | U12: 5160 | V12: 5542 | W12: 5319 | X12: 3734 | Y12: 3835 | Z12: 13830 | AA12: 6776 | AB12: 3808 | AC12: 9904 | AD12: 6303 | AE12: 4842 | AF12: 10922 | AG12: 2834 | AH12: 3315 | AI12: 12955 | AJ12: 4306 | AK12: 9053 | AL12: 9454 | AM12: 8805 | AN12: 5074 | AO12: 3363 | AP12: 9726 | AQ12: 5792 | AR12: 2120 | AS12: 5960 | AT12: 7576 | AU12: 2889 | AV12: 12446 | AW12: 3624 | AX12: 9376 | AY12: 10286 | AZ12: 8642 | BA12: 8666 | BB12: 11590 | BC12: 2727 | BD12: 3040 | BE12: 2213
A13: 44655 | B13: 6.363 | C13: 7.8348 | D13: 4276.158 | E13: 809.2 | F13: 21740 | G13: 3997 | H13: 3244 | I13: 926 | J13: 5876 | K13: 648.7 | L13: 20280 | M13: 73160 | N13: 22640 | O13: 26875 | P13: 15740 | Q13: 217910 | R13: 340950 | S13: 396.26 | T13: 5038 | U13: 5160 | V13: 5542 | W13: 5319 | X13: 3734 | Y13: 3835 | Z13: 13830 | AA13: 6776 | AB13: 3808 | AC13: 9904 | AD13: 6303 | AE13: 4842 | AF13: 10922 | AG13: 2834 | AH13: 3315 | AI13: 12955 | AJ13: 4306 | AK13: 9053 | AL13: 9454 | AM13: 8805 | AN13: 5074 | AO13: 3363 | AP13: 9726 | AQ13: 5792 | AR13: 2120 | AS13: 5960 | AT13: 7576 | AU13: 2889 | AV13: 12446 | AW13: 3624 | AX13: 9376 | AY13: 10286 | AZ13: 8642 | BA13: 8666 | BB13: 11590 | BC13: 2727 | BD13: 3040 | BE13: 2307
A14: 44652 | B14: 6.3625 | C14: 7.8341 | D14: 4276.158 | E14: 809.2 | F14: 21740 | G14: 3997 | H14: 3244 | I14: 926 | J14: 5876 | K14: 648.7 | L14: 20280 | M14: 73160 | N14: 22640 | O14: 26875 | P14: 15740 | Q14: 217910 | R14: 340950 | S14: 396.26 | T14: 5038 | U14: 5160 | V14: 5542 | W14: 5319 | X14: 3734 | Y14: 3835 | Z14: 13830 | AA14: 6776 | AB14: 3808 | AC14: 9904 | AD14: 6303 | AE14: 4842 | AF14: 10922 | AG14: 2834 | AH14: 3315 | AI14: 12955 | AJ14: 4306 | AK14: 9053 | AL14: 9454 | AM14: 8805 | AN14: 5074 | AO14: 3363 | AP14: 9726 | AQ14: 5792 | AR14: 2120 | AS14: 5960 | AT14: 7576 | AU14: 2889 | AV14: 12446 | AW14: 3624 | AX14: 9376 | AY14: 10286 | AZ14: 8642 | BA14: 8666 | BB14: 11590 | BC14: 2727 | BD14: 3040 | BE14: 2357
A15: 44651 | B15: 6.3398 | C15: 7.8328 | D15: 4222.5968 | E15: 805 | F15: 21755 | G15: 3935 | H15: 3186 | I15: 897 | J15: 6166 | K15: 675.1 | L15: 20185 | M15: 73320 | N15: 22730 | O15: 26785 | P15: 15815 | Q15: 217780 | R15: 344840 | S15: 394.34 | T15: 5011 | U15: 5061 | V15: 5542 | W15: 5218 | X15: 3967 | Y15: 3918 | Z15: 13705 | AA15: 6770 | AB15: 4038 | AC15: 10174 | AD15: 6320 | AE15: 5074 | AF15: 11496 | AG15: 2840 | AH15: 3326 | AI15: 13005 | AJ15: 4332 | AK15: 9169 | AL15: 9242 | AM15: 8920 | AN15: 5128 | AO15: 3393 | AP15: 9674 | AQ15: 5799 | AR15: 2111 | AS15: 6072 | AT15: 7718 | AU15: 2917 | AV15: 12605 | AW15: 3848 | AX15: 9672 | AY15: 9984 | AZ15: 8652 | BA15: 8288 | BB15: 11640 | BC15: 2784 | BD15: 3014 | BE15: 2358
A16: 44650 | B16: 6.3477 | C16: 7.8271 | D16: 4254.0989 | E16: 814 | F16: 21745 | G16: 3873 | H16: 3172 | I16: 895 | J16: 6168 | K16: 690.7 | L16: 20730 | M16: 74210 | N16: 22935 | O16: 26775 | P16: 15705 | Q16: 230050 | R16: 346400 | S16: 394.74 | T16: 5061 | U16: 5034 | V16: 5540 | W16: 5264 | X16: 4044 | Y16: 3975 | Z16: 13585 | AA16: 6848 | AB16: 4105 | AC16: 10028 | AD16: 6215 | AE16: 5033 | AF16: 11520 | AG16: 2842 | AH16: 3361 | AI16: 12895 | AJ16: 4330 | AK16: 9291 | AL16: 9319 | AM16: 9079 | AN16: 5249 | AO16: 3386 | AP16: 9876 | AQ16: 5817 | AR16: 2125 | AS16: 6082 | AT16: 7704 | AU16: 3027 | AV16: 12484 | AW16: 3831 | AX16: 9672 | AY16: 9858 | AZ16: 8668 | BA16: 8214 | BB16: 11465 | BC16: 2796 | BD16: 3025 | BE16: 2369
A17: 44649 | B17: 6.3607 | C17: 7.8272 | D17: 4134.1441 | E17: 840.6 | F17: 21740 | G17: 3844 | H17: 3193.5 | I17: 867.5 | J17: 6170 | K17: 677.8 | L17: 20270 | M17: 73570 | N17: 22960 | O17: 26580 | P17: 15590 | Q17: 223130 | R17: 347010 | S17: 395.54 | T17: 5118 | U17: 5012 | V17: 5524 | W17: 5255 | X17: 4030 | Y17: 3978 | Z17: 13360 | AA17: 6962 | AB17: 4187 | AC17: 10122 | AD17: 6153 | AE17: 5124 | AF17: 11666 | AG17: 2855 | AH17: 3360 | AI17: 12990 | AJ17: 4367 | AK17: 9310 | AL17: 9291 | AM17: 9149 | AN17: 5275 | AO17: 3393 | AP17: 9868 | AQ17: 5866 | AR17: 2069 | AS17: 6044 | AT17: 7692 | AU17: 3054 | AV17: 12599 | AW17: 3911 | AX17: 9704 | AY17: 9890 | AZ17: 8810 | BA17: 9900 | BB17: 11615 | BC17: 2759 | BD17: 2970 | BE17: 2417
... A77: 44565 | B77: 6.3726 | C77: 7.7941 | D77: 4917.7653 | E77: 713.8 | F77: 20670 | G77: 3047 | H77: 2337 | I77: 689 | J77: 4875 | K77: 494.1 | L77: 17230 | M77: 69730 | N77: 20210 | O77: 24050 | P77: 15385 | Q77: 152570 | R77: 289950 | S77: 371.74 | T77: 4774 | U77: 4395 | V77: 4451 | W77: 4499 | X77: 2855 | Y77: 3320 | Z77: 14695 | AA77: 6078 | AB77: 3250 | AC77: 8914 | AD77: 5847 | AE77: 4375 | AF77: 8682 | AG77: 2702 | AH77: 3005 | AI77: 14165 | AJ77: 4165 | AK77: 8736 | AL77: 8578 | AM77: 8287 | AN77: 5051 | AO77: 3308 | AP77: 8606 | AQ77: 5804 | AR77: 1703 | AS77: 5046 | AT77: 7108 | AU77: 2591 | AV77: 12039 | AW77: 2981 | AX77: 8184 | AY77: 8266 | AZ77: 8044 | BA77: 8177 | BB77: 12755 | BC77: 2472 | BD77: 2221 | BE77: 2285

Sheet 中国汇率&amp;amp;期货（ln）
B5: =LN('中国汇率&期货（数据表）'!B5) | C5: =LN('中国汇率&期货（数据表）'!C5) | D5: =LN('中国汇率&期货（数据表）'!D5) | E5: =LN('中国汇率&期货（数据表）'!E5) | F5: =LN('中国汇率&期货（数据表）'!F5) | G5: =LN('中国汇率&期货（数据表）'!G5) | H5: =LN('中国汇率&期货（数据表）'!H5) | I5: =LN('中国汇率&期货（数据表）'!I5) | ... BE5: =LN('中国汇率&期货（数据表）'!BE5)
B6: =LN('中国汇率&期货（数据表）'!B6) | C6: =LN('中国汇率&期货（数据表）'!C6) | D6: =LN('中国汇率&期货（数据表）'!D6) | E6: =LN('中国汇率&期货（数据表）'!E6) | F6: =LN('中国汇率&期货（数据表）'!F6) | G6: =LN('中国汇率&期货（数据表）'!G6) | H6: =LN('中国汇率&期货（数据表）'!H6) | I6: =LN('中国汇率&期货（数据表）'!I6) | ... BE6: =LN('中国汇率&期货（数据表）'!BE6)
B7: =LN('中国汇率&期货（数据表）'!B7) | C7: =LN('中国汇率&期货（数据表）'!C7) | D7: =LN('中国汇率&期货（数据表）'!D7) | E7: =LN('中国汇率&期货（数据表）'!E7) | F7: =LN('中国汇率&期货（数据表）'!F7) | G7: =LN('中国汇率&期货（数据表）'!G7) | H7: =LN('中国汇率&期货（数据表）'!H7) | I7: =LN('中国汇率&期货（数据表）'!I7) | ... BE7: =LN('中国汇率&期货（数据表）'!BE7)
B8: =LN('中国汇率&期货（数据表）'!B8) | C8: =LN('中国汇率&期货（数据表）'!C8) | D8: =LN('中国汇率&期货（数据表）'!D8) | E8: =LN('中国汇率&期货（数据表）'!E8) | F8: =LN('中国汇率&期货（数据表）'!F8) | G8: =LN('中国汇率&期货（数据表）'!G8) | H8: =LN('中国汇率&期货（数据表）'!H8) | I8: =LN('中国汇率&期货（数据表）'!I8) | ... BE8: =LN('中国汇率&期货（数据表）'!BE8)
B9: =LN('中国汇率&期货（数据表）'!B9) | C9: =LN('中国汇率&期货（数据表）'!C9) | D9: =LN('中国汇率&期货（数据表）'!D9) | E9: =LN('中国汇率&期货（数据表）'!E9) | F9: =LN('中国汇率&期货（数据表）'!F9) | G9: =LN('中国汇率&期货（数据表）'!G9) | H9: =LN('中国汇率&期货（数据表）'!H9) | I9: =LN('中国汇率&期货（数据表）'!I9) | ... BE9: =LN('中国汇率&期货（数据表）'!BE9)
B10: =LN('中国汇率&期货（数据表）'!B10) | C10: =LN('中国汇率&期货（数据表）'!C10) | D10: =LN('中国汇率&期货（数据表）'!D10) | E10: =LN('中国汇率&期货（数据表）'!E10) | F10: =LN('中国汇率&期货（数据表）'!F10) | G10: =LN('中国汇率&期货（数据表）'!G10) | H10: =LN('中国汇率&期货（数据表）'!H10) | I10: =LN('中国汇率&期货（数据表）'!I10) | ... BE10: =LN('中国汇率&期货（数据表）'!BE10)
B11: =LN('中国汇率&期货（数据表）'!B11) | C11: =LN('中国汇率&期货（数据表）'!C11) | D11: =LN('中国汇率&期货（数据表）'!D11) | E11: =LN('中国汇率&期货（数据表）'!E11) | F11: =LN('中国汇率&期货（数据表）'!F11) | G11: =LN('中国汇率&期货（数据表）'!G11) | H11: =LN('中国汇率&期货（数据表）'!H11) | I11: =LN('中国汇率&期货（数据表）'!I11) | ... BE11: =LN('中国汇率&期货（数据表）'!BE11)
B12: =LN('中国汇率&期货（数据表）'!B12) | C12: =LN('中国汇率&期货（数据表）'!C12) | D12: =LN('中国汇率&期货（数据表）'!D12) | E12: =LN('中国汇率&期货（数据表）'!E12) | F12: =LN('中国汇率&期货（数据表）'!F12) | G12: =LN('中国汇率&期货（数据表）'!G12) | H12: =LN('中国汇率&期货（数据表）'!H12) | I12: =LN('中国汇率&期货（数据表）'!I12) | ... BE12: =LN('中国汇率&期货（数据表）'!BE12)
B13: =LN('中国汇率&期货（数据表）'!B13) | C13: =LN('中国汇率&期货（数据表）'!C13) | D13: =LN('中国汇率&期货（数据表）'!D13) | E13: =LN('中国汇率&期货（数据表）'!E13) | F13: =LN('中国汇率&期货（数据表）'!F13) | G13: =LN('中国汇率&期货（数据表）'!G13) | H13: =LN('中国汇率&期货（数据表）'!H13) | I13: =LN('中国汇率&期货（数据表）'!I13) | ... BE13: =LN('中国汇率&期货（数据表）'!BE13)
B14: =LN('中国汇率&期货（数据表）'!B14) | C14: =LN('中国汇率&期货（数据表）'!C14) | D14: =LN('中国汇率&期货（数据表）'!D14) | E14: =LN('中国汇率&期货（数据表）'!E14) | F14: =LN('中国汇率&期货（数据表）'!F14) | G14: =LN('中国汇率&期货（数据表）'!G14) | H14: =LN('中国汇率&期货（数据表）'!H14) | I14: =LN('中国汇率&期货（数据表）'!I14) | ... BE14: =LN('中国汇率&期货（数据表）'!BE14)
B15: =LN('中国汇率&期货（数据表）'!B15) | C15: =LN('中国汇率&期货（数据表）'!C15) | D15: =LN('中国汇率&期货（数据表）'!D15) | E15: =LN('中国汇率&期货（数据表）'!E15) | F15: =LN('中国汇率&期货（数据表）'!F15) | G15: =LN('中国汇率&期货（数据表）'!G15) | H15: =LN('中国汇率&期货（数据表）'!H15) | I15: =LN('中国汇率&期货（数据表）'!I15) | ... BE15: =LN('中国汇率&期货（数据表）'!BE15)
B16: =LN('中国汇率&期货（数据表）'!B16) | C16: =LN('中国汇率&期货（数据表）'!C16) | D16: =LN('中国汇率&期货（数据表）'!D16) | E16: =LN('中国汇率&期货（数据表）'!E16) | F16: =LN('中国汇率&期货（数据表）'!F16) | G16: =LN('中国汇率&期货（数据表）'!G16) | H16: =LN('中国汇率&期货（数据表）'!H16) | I16: =LN('中国汇率&期货（数据表）'!I16) | ... BE16: =LN('中国汇率&期货（数据表）'!BE16)
... B77: =LN('中国汇率&期货（数据表）'!B77) | C77: =LN('中国汇率&期货（数据表）'!C77) | D77: =LN('中国汇率&期货（数据表）'!D77) | E77: =LN('中国汇率&期货（数据表）'!E77) | F77: =LN('中国汇率&期货（数据表）'!F77) | G77: =LN('中国汇率&期货（数据表）'!G77) | H77: =LN('中国汇率&期货（数据表）'!H77) | I77: =LN('中国汇率&期货（数据表）'!I77) | ... BE77: =LN('中国汇率&期货（数据表）'!BE77)

Sheet 中国汇率&amp;amp;期货（change）
B5: ='中国汇率&期货（ln）'!B5-'中国汇率&期货（ln）'!B24 | C5: ='中国汇率&期货（ln）'!C5-'中国汇率&期货（ln）'!C24 | D5: ='中国汇率&期货（ln）'!D5-'中国汇率&期货（ln）'!D24 | E5: ='中国汇率&期货（ln）'!E5-'中国汇率&期货（ln）'!E24 | F5: ='中国汇率&期货（ln）'!F5-'中国汇率&期货（ln）'!F24 | G5: ='中国汇率&期货（ln）'!G5-'中国汇率&期货（ln）'!G24 | H5: ='中国汇率&期货（ln）'!H5-'中国汇率&期货（ln）'!H24 | I5: ='中国汇率&期货（ln）'!I5-'中国汇率&期货（ln）'!I24 | ... BE5: ='中国汇率&期货（ln）'!BE5-'中国汇率&期货（ln）'!BE24
B6: ='中国汇率&期货（ln）'!B6-'中国汇率&期货（ln）'!B25 | C6: ='中国汇率&期货（ln）'!C6-'中国汇率&期货（ln）'!C25 | D6: ='中国汇率&期货（ln）'!D6-'中国汇率&期货（ln）'!D25 | E6: ='中国汇率&期货（ln）'!E6-'中国汇率&期货（ln）'!E25 | F6: ='中国汇率&期货（ln）'!F6-'中国汇率&期货（ln）'!F25 | G6: ='中国汇率&期货（ln）'!G6-'中国汇率&期货（ln）'!G25 | H6: ='中国汇率&期货（ln）'!H6-'中国汇率&期货（ln）'!H25 | I6: ='中国汇率&期货（ln）'!I6-'中国汇率&期货（ln）'!I25 | ... BE6: ='中国汇率&期货（ln）'!BE6-'中国汇率&期货（ln）'!BE25
B7: ='中国汇率&期货（ln）'!B7-'中国汇率&期货（ln）'!B26 | C7: ='中国汇率&期货（ln）'!C7-'中国汇率&期货（ln）'!C26 | D7: ='中国汇率&期货（ln）'!D7-'中国汇率&期货（ln）'!D26 | E7: ='中国汇率&期货（ln）'!E7-'中国汇率&期货（ln）'!E26 | F7: ='中国汇率&期货（ln）'!F7-'中国汇率&期货（ln）'!F26 | G7: ='中国汇率&期货（ln）'!G7-'中国汇率&期货（ln）'!G26 | H7: ='中国汇率&期货（ln）'!H7-'中国汇率&期货（ln）'!H26 | I7: ='中国汇率&期货（ln）'!I7-'中国汇率&期货（ln）'!I26 | ... BE7: ='中国汇率&期货（ln）'!BE7-'中国汇率&期货（ln）'!BE26
B8: ='中国汇率&期货（ln）'!B8-'中国汇率&期货（ln）'!B27 | C8: ='中国汇率&期货（ln）'!C8-'中国汇率&期货（ln）'!C27 | D8: ='中国汇率&期货（ln）'!D8-'中国汇率&期货（ln）'!D27 | E8: ='中国汇率&期货（ln）'!E8-'中国汇率&期货（ln）'!E27 | F8: ='中国汇率&期货（ln）'!F8-'中国汇率&期货（ln）'!F27 | G8: ='中国汇率&期货（ln）'!G8-'中国汇率&期货（ln）'!G27 | H8: ='中国汇率&期货（ln）'!H8-'中国汇率&期货（ln）'!H27 | I8: ='中国汇率&期货（ln）'!I8-'中国汇率&期货（ln）'!I27 | ... BE8: ='中国汇率&期货（ln）'!BE8-'中国汇率&期货（ln）'!BE27
B9: ='中国汇率&期货（ln）'!B9-'中国汇率&期货（ln）'!B28 | C9: ='中国汇率&期货（ln）'!C9-'中国汇率&期货（ln）'!C28 | D9: ='中国汇率&期货（ln）'!D9-'中国汇率&期货（ln）'!D28 | E9: ='中国汇率&期货（ln）'!E9-'中国汇率&期货（ln）'!E28 | F9: ='中国汇率&期货（ln）'!F9-'中国汇率&期货（ln）'!F28 | G9: ='中国汇率&期货（ln）'!G9-'中国汇率&期货（ln）'!G28 | H9: ='中国汇率&期货（ln）'!H9-'中国汇率&期货（ln）'!H28 | I9: ='中国汇率&期货（ln）'!I9-'中国汇率&期货（ln）'!I28 | ... BE9: ='中国汇率&期货（ln）'!BE9-'中国汇率&期货（ln）'!BE28
B10: ='中国汇率&期货（ln）'!B10-'中国汇率&期货（ln）'!B29 | C10: ='中国汇率&期货（ln）'!C10-'中国汇率&期货（ln）'!C29 | D10: ='中国汇率&期货（ln）'!D10-'中国汇率&期货（ln）'!D29 | E10: ='中国汇率&期货（ln）'!E10-'中国汇率&期货（ln）'!E29 | F10: ='中国汇率&期货（ln）'!F10-'中国汇率&期货（ln）'!F29 | G10: ='中国汇率&期货（ln）'!G10-'中国汇率&期货（ln）'!G29 | H10: ='中国汇率&期货（ln）'!H10-'中国汇率&期货（ln）'!H29 | I10: ='中国汇率&期货（ln）'!I10-'中国汇率&期货（ln）'!I29 | ... BE10: ='中国汇率&期货（ln）'!BE10-'中国汇率&期货（ln）'!BE29
B11: ='中国汇率&期货（ln）'!B11-'中国汇率&期货（ln）'!B30 | C11: ='中国汇率&期货（ln）'!C11-'中国汇率&期货（ln）'!C30 | D11: ='中国汇率&期货（ln）'!D11-'中国汇率&期货（ln）'!D30 | E11: ='中国汇率&期货（ln）'!E11-'中国汇率&期货（ln）'!E30 | F11: ='中国汇率&期货（ln）'!F11-'中国汇率&期货（ln）'!F30 | G11: ='中国汇率&期货（ln）'!G11-'中国汇率&期货（ln）'!G30 | H11: ='中国汇率&期货（ln）'!H11-'中国汇率&期货（ln）'!H30 | I11: ='中国汇率&期货（ln）'!I11-'中国汇率&期货（ln）'!I30 | ... BE11: ='中国汇率&期货（ln）'!BE11-'中国汇率&期货（ln）'!BE30
B12: ='中国汇率&期货（ln）'!B12-'中国汇率&期货（ln）'!B31 | C12: ='中国汇率&期货（ln）'!C12-'中国汇率&期货（ln）'!C31 | D12: ='中国汇率&期货（ln）'!D12-'中国汇率&期货（ln）'!D31 | E12: ='中国汇率&期货（ln）'!E12-'中国汇率&期货（ln）'!E31 | F12: ='中国汇率&期货（ln）'!F12-'中国汇率&期货（ln）'!F31 | G12: ='中国汇率&期货（ln）'!G12-'中国汇率&期货（ln）'!G31 | H12: ='中国汇率&期货（ln）'!H12-'中国汇率&期货（ln）'!H31 | I12: ='中国汇率&期货（ln）'!I12-'中国汇率&期货（ln）'!I31 | ... BE12: ='中国汇率&期货（ln）'!BE12-'中国汇率&期货（ln）'!BE31
B13: ='中国汇率&期货（ln）'!B13-'中国汇率&期货（ln）'!B32 | C13: ='中国汇率&期货（ln）'!C13-'中国汇率&期货（ln）'!C32 | D13: ='中国汇率&期货（ln）'!D13-'中国汇率&期货（ln）'!D32 | E13: ='中国汇率&期货（ln）'!E13-'中国汇率&期货（ln）'!E32 | F13: ='中国汇率&期货（ln）'!F13-'中国汇率&期货（ln）'!F32 | G13: ='中国汇率&期货（ln）'!G13-'中国汇率&期货（ln）'!G32 | H13: ='中国汇率&期货（ln）'!H13-'中国汇率&期货（ln）'!H32 | I13: ='中国汇率&期货（ln）'!I13-'中国汇率&期货（ln）'!I32 | ... BE13: ='中国汇率&期货（ln）'!BE13-'中国汇率&期货（ln）'!BE32
B14: ='中国汇率&期货（ln）'!B14-'中国汇率&期货（ln）'!B33 | C14: ='中国汇率&期货（ln）'!C14-'中国汇率&期货（ln）'!C33 | D14: ='中国汇率&期货（ln）'!D14-'中国汇率&期货（ln）'!D33 | E14: ='中国汇率&期货（ln）'!E14-'中国汇率&期货（ln）'!E33 | F14: ='中国汇率&期货（ln）'!F14-'中国汇率&期货（ln）'!F33 | G14: ='中国汇率&期货（ln）'!G14-'中国汇率&期货（ln）'!G33 | H14: ='中国汇率&期货（ln）'!H14-'中国汇率&期货（ln）'!H33 | I14: ='中国汇率&期货（ln）'!I14-'中国汇率&期货（ln）'!I33 | ... BE14: ='中国汇率&期货（ln）'!BE14-'中国汇率&期货（ln）'!BE33
B15: ='中国汇率&期货（ln）'!B15-'中国汇率&期货（ln）'!B34 | C15: ='中国汇率&期货（ln）'!C15-'中国汇率&期货（ln）'!C34 | D15: ='中国汇率&期货（ln）'!D15-'中国汇率&期货（ln）'!D34 | E15: ='中国汇率&期货（ln）'!E15-'中国汇率&期货（ln）'!E34 | F15: ='中国汇率&期货（ln）'!F15-'中国汇率&期货（ln）'!F34 | G15: ='中国汇率&期货（ln）'!G15-'中国汇率&期货（ln）'!G34 | H15: ='中国汇率&期货（ln）'!H15-'中国汇率&期货（ln）'!H34 | I15: ='中国汇率&期货（ln）'!I15-'中国汇率&期货（ln）'!I34 | ... BE15: ='中国汇率&期货（ln）'!BE15-'中国汇率&期货（ln）'!BE34
B16: ='中国汇率&期货（ln）'!B16-'中国汇率&期货（ln）'!B35 | C16: ='中国汇率&期货（ln）'!C16-'中国汇率&期货（ln）'!C35 | D16: ='中国汇率&期货（ln）'!D16-'中国汇率&期货（ln）'!D35 | E16: ='中国汇率&期货（ln）'!E16-'中国汇率&期货（ln）'!E35 | F16: ='中国汇率&期货（ln）'!F16-'中国汇率&期货（ln）'!F35 | G16: ='中国汇率&期货（ln）'!G16-'中国汇率&期货（ln）'!G35 | H16: ='中国汇率&期货（ln）'!H16-'中国汇率&期货（ln）'!H35 | I16: ='中国汇率&期货（ln）'!I16-'中国汇率&期货（ln）'!I35 | ... BE16: ='中国汇率&期货（ln）'!BE16-'中国汇率&期货（ln）'!BE35
... B77: ='中国汇率&期货（ln）'!B77-'中国汇率&期货（ln）'!B96 | C77: ='中国汇率&期货（ln）'!C77-'中国汇率&期货（ln）'!C96 | D77: ='中国汇率&期货（ln）'!D77-'中国汇率&期货（ln）'!D96 | E77: ='中国汇率&期货（ln）'!E77-'中国汇率&期货（ln）'!E96 | F77: ='中国汇率&期货（ln）'!F77-'中国汇率&期货（ln）'!F96 | G77: ='中国汇率&期货（ln）'!G77-'中国汇率&期货（ln）'!G96 | H77: ='中国汇率&期货（ln）'!H77-'中国汇率&期货（ln）'!H96 | I77: ='中国汇率&期货（ln）'!I77-'中国汇率&期货（ln）'!I96 | ... BE77: ='中国汇率&期货（ln）'!BE77-'中国汇率&期货（ln）'!BE96

Sheet 中国汇率&amp;amp;期货（vol）
B5: =_xlfn.STDEV.P('中国汇率&期货（ln）'!B5:B24) | C5: =_xlfn.STDEV.P('中国汇率&期货（ln）'!C5:C24) | D5: =_xlfn.STDEV.P('中国汇率&期货（ln）'!D5:D24) | E5: =_xlfn.STDEV.P('中国汇率&期货（ln）'!E5:E24) | F5: =_xlfn.STDEV.P('中国汇率&期货（ln）'!F5:F24) | G5: =_xlfn.STDEV.P('中国汇率&期货（ln）'!G5:G24) | H5: =_xlfn.STDEV.P('中国汇率&期货（ln）'!H5:H24) | I5: =_xlfn.STDEV.P('中国汇率&期货（ln）'!I5:I24) | ... BE5: =_xlfn.STDEV.P('中国汇率&期货（ln）'!BE5:BE24)
B6: =_xlfn.STDEV.P('中国汇率&期货（ln）'!B6:B25) | C6: =_xlfn.STDEV.P('中国汇率&期货（ln）'!C6:C25) | D6: =_xlfn.STDEV.P('中国汇率&期货（ln）'!D6:D25) | E6: =_xlfn.STDEV.P('中国汇率&期货（ln）'!E6:E25) | F6: =_xlfn.STDEV.P('中国汇率&期货（ln）'!F6:F25) | G6: =_xlfn.STDEV.P('中国汇率&期货（ln）'!G6:G25) | H6: =_xlfn.STDEV.P('中国汇率&期货（ln）'!H6:H25) | I6: =_xlfn.STDEV.P('中国汇率&期货（ln）'!I6:I25) | ... BE6: =_xlfn.STDEV.P('中国汇率&期货（ln）'!BE6:BE25)
B7: =_xlfn.STDEV.P('中国汇率&期货（ln）'!B7:B26) | C7: =_xlfn.STDEV.P('中国汇率&期货（ln）'!C7:C26) | D7: =_xlfn.STDEV.P('中国汇率&期货（ln）'!D7:D26) | E7: =_xlfn.STDEV.P('中国汇率&期货（ln）'!E7:E26) | F7: =_xlfn.STDEV.P('中国汇率&期货（ln）'!F7:F26) | G7: =_xlfn.STDEV.P('中国汇率&期货（ln）'!G7:G26) | H7: =_xlfn.STDEV.P('中国汇率&期货（ln）'!H7:H26) | I7: =_xlfn.STDEV.P('中国汇率&期货（ln）'!I7:I26) | ... BE7: =_xlfn.STDEV.P('中国汇率&期货（ln）'!BE7:BE26)
B8: =_xlfn.STDEV.P('中国汇率&期货（ln）'!B8:B27) | C8: =_xlfn.STDEV.P('中国汇率&期货（ln）'!C8:C27) | D8: =_xlfn.STDEV.P('中国汇率&期货（ln）'!D8:D27) | E8: =_xlfn.STDEV.P('中国汇率&期货（ln）'!E8:E27) | F8: =_xlfn.STDEV.P('中国汇率&期货（ln）'!F8:F27) | G8: =_xlfn.STDEV.P('中国汇率&期货（ln）'!G8:G27) | H8: =_xlfn.STDEV.P('中国汇率&期货（ln）'!H8:H27) | I8: =_xlfn.STDEV.P('中国汇率&期货（ln）'!I8:I27) | ... BE8: =_xlfn.STDEV.P('中国汇率&期货（ln）'!BE8:BE27)
B9: =_xlfn.STDEV.P('中国汇率&期货（ln）'!B9:B28) | C9: =_xlfn.STDEV.P('中国汇率&期货（ln）'!C9:C28) | D9: =_xlfn.STDEV.P('中国汇率&期货（ln）'!D9:D28) | E9: =_xlfn.STDEV.P('中国汇率&期货（ln）'!E9:E28) | F9: =_xlfn.STDEV.P('中国汇率&期货（ln）'!F9:F28) | G9: =_xlfn.STDEV.P('中国汇率&期货（ln）'!G9:G28) | H9: =_xlfn.STDEV.P('中国汇率&期货（ln）'!H9:H28) | I9: =_xlfn.STDEV.P('中国汇率&期货（ln）'!I9:I28) | ... BE9: =_xlfn.STDEV.P('中国汇率&期货（ln）'!BE9:BE28)
B10: =_xlfn.STDEV.P('中国汇率&期货（ln）'!B10:B29) | C10: =_xlfn.STDEV.P('中国汇率&期货（ln）'!C10:C29) | D10: =_xlfn.STDEV.P('中国汇率&期货（ln）'!D10:D29) | E10: =_xlfn.STDEV.P('中国汇率&期货（ln）'!E10:E29) | F10: =_xlfn.STDEV.P('中国汇率&期货（ln）'!F10:F29) | G10: =_xlfn.STDEV.P('中国汇率&期货（ln）'!G10:G29) | H10: =_xlfn.STDEV.P('中国汇率&期货（ln）'!H10:H29) | I10: =_xlfn.STDEV.P('中国汇率&期货（ln）'!I10:I29) | ... BE10: =_xlfn.STDEV.P('中国汇率&期货（ln）'!BE10:BE29)
B11: =_xlfn.STDEV.P('中国汇率&期货（ln）'!B11:B30) | C11: =_xlfn.STDEV.P('中国汇率&期货（ln）'!C11:C30) | D11: =_xlfn.STDEV.P('中国汇率&期货（ln）'!D11:D30) | E11: =_xlfn.STDEV.P('中国汇率&期货（ln）'!E11:E30) | F11: =_xlfn.STDEV.P('中国汇率&期货（ln）'!F11:F30) | G11: =_xlfn.STDEV.P('中国汇率&期货（ln）'!G11:G30) | H11: =_xlfn.STDEV.P('中国汇率&期货（ln）'!H11:H30) | I11: =_xlfn.STDEV.P('中国汇率&期货（ln）'!I11:I30) | ... BE11: =_xlfn.STDEV.P('中国汇率&期货（ln）'!BE11:BE30)
B12: =_xlfn.STDEV.P('中国汇率&期货（ln）'!B12:B31) | C12: =_xlfn.STDEV.P('中国汇率&期货（ln）'!C12:C31) | D12: =_xlfn.STDEV.P('中国汇率&期货（ln）'!D12:D31) | E12: =_xlfn.STDEV.P('中国汇率&期货（ln）'!E12:E31) | F12: =_xlfn.STDEV.P('中国汇率&期货（ln）'!F12:F31) | G12: =_xlfn.STDEV.P('中国汇率&期货（ln）'!G12:G31) | H12: =_xlfn.STDEV.P('中国汇率&期货（ln）'!H12:H31) | I12: =_xlfn.STDEV.P('中国汇率&期货（ln）'!I12:I31) | ... BE12: =_xlfn.STDEV.P('中国汇率&期货（ln）'!BE12:BE31)
B13: =_xlfn.STDEV.P('中国汇率&期货（ln）'!B13:B32) | C13: =_xlfn.STDEV.P('中国汇率&期货（ln）'!C13:C32) | D13: =_xlfn.STDEV.P('中国汇率&期货（ln）'!D13:D32) | E13: =_xlfn.STDEV.P('中国汇率&期货（ln）'!E13:E32) | F13: =_xlfn.STDEV.P('中国汇率&期货（ln）'!F13:F32) | G13: =_xlfn.STDEV.P('中国汇率&期货（ln）'!G13:G32) | H13: =_xlfn.STDEV.P('中国汇率&期货（ln）'!H13:H32) | I13: =_xlfn.STDEV.P('中国汇率&期货（ln）'!I13:I32) | ... BE13: =_xlfn.STDEV.P('中国汇率&期货（ln）'!BE13:BE32)
B14: =_xlfn.STDEV.P('中国汇率&期货（ln）'!B14:B33) | C14: =_xlfn.STDEV.P('中国汇率&期货（ln）'!C14:C33) | D14: =_xlfn.STDEV.P('中国汇率&期货（ln）'!D14:D33) | E14: =_xlfn.STDEV.P('中国汇率&期货（ln）'!E14:E33) | F14: =_xlfn.STDEV.P('中国汇率&期货（ln）'!F14:F33) | G14: =_xlfn.STDEV.P('中国汇率&期货（ln）'!G14:G33) | H14: =_xlfn.STDEV.P('中国汇率&期货（ln）'!H14:H33) | I14: =_xlfn.STDEV.P('中国汇率&期货（ln）'!I14:I33) | ... BE14: =_xlfn.STDEV.P('中国汇率&期货（ln）'!BE14:BE33)
B15: =_xlfn.STDEV.P('中国汇率&期货（ln）'!B15:B34) | C15: =_xlfn.STDEV.P('中国汇率&期货（ln）'!C15:C34) | D15: =_xlfn.STDEV.P('中国汇率&期货（ln）'!D15:D34) | E15: =_xlfn.STDEV.P('中国汇率&期货（ln）'!E15:E34) | F15: =_xlfn.STDEV.P('中国汇率&期货（ln）'!F15:F34) | G15: =_xlfn.STDEV.P('中国汇率&期货（ln）'!G15:G34) | H15: =_xlfn.STDEV.P('中国汇率&期货（ln）'!H15:H34) | I15: =_xlfn.STDEV.P('中国汇率&期货（ln）'!I15:I34) | ... BE15: =_xlfn.STDEV.P('中国汇率&期货（ln）'!BE15:BE34)
B16: =_xlfn.STDEV.P('中国汇率&期货（ln）'!B16:B35) | C16: =_xlfn.STDEV.P('中国汇率&期货（ln）'!C16:C35) | D16: =_xlfn.STDEV.P('中国汇率&期货（ln）'!D16:D35) | E16: =_xlfn.STDEV.P('中国汇率&期货（ln）'!E16:E35) | F16: =_xlfn.STDEV.P('中国汇率&期货（ln）'!F16:F35) | G16: =_xlfn.STDEV.P('中国汇率&期货（ln）'!G16:G35) | H16: =_xlfn.STDEV.P('中国汇率&期货（ln）'!H16:H35) | I16: =_xlfn.STDEV.P('中国汇率&期货（ln）'!I16:I35) | ... BE16: =_xlfn.STDEV.P('中国汇率&期货（ln）'!BE16:BE35)
... B77: =_xlfn.STDEV.P('中国汇率&期货（ln）'!B77:B96) | C77: =_xlfn.STDEV.P('中国汇率&期货（ln）'!C77:C96) | D77: =_xlfn.STDEV.P('中国汇率&期货（ln）'!D77:D96) | E77: =_xlfn.STDEV.P('中国汇率&期货（ln）'!E77:E96) | F77: =_xlfn.STDEV.P('中国汇率&期货（ln）'!F77:F96) | G77: =_xlfn.STDEV.P('中国汇率&期货（ln）'!G77:G96) | H77: =_xlfn.STDEV.P('中国汇率&期货（ln）'!H77:H96) | I77: =_xlfn.STDEV.P('中国汇率&期货（ln）'!I77:I96) | ... BE77: =_xlfn.STDEV.P('中国汇率&期货（ln）'!BE77:BE96)

Sheet 中国汇率&amp;amp;期货（成果标准）
B3: ='中国汇率&期货（数据表）'!B3 | C3: ='中国汇率&期货（数据表）'!C3 | D3: ='中国汇率&期货（数据表）'!D3 | E3: ='中国汇率&期货（数据表）'!E3 | F3: ='中国汇率&期货（数据表）'!F3 | G3: ='中国汇率&期货（数据表）'!G3 | H3: ='中国汇率&期货（数据表）'!H3 | I3: ='中国汇率&期货（数据表）'!I3 | ... BE3: ='中国汇率&期货（数据表）'!BE3
B4: ='中国汇率&期货（数据表）'!B4 | C4: ='中国汇率&期货（数据表）'!C4 | D4: ='中国汇率&期货（数据表）'!D4 | E4: ='中国汇率&期货（数据表）'!E4 | F4: ='中国汇率&期货（数据表）'!F4 | G4: ='中国汇率&期货（数据表）'!G4 | H4: ='中国汇率&期货（数据表）'!H4 | I4: ='中国汇率&期货（数据表）'!I4 | ... BE4: ='中国汇率&期货（数据表）'!BE4
B5: ='中国汇率&期货（change）'!B5/'中国汇率&期货（vol）'!B5 | C5: ='中国汇率&期货（change）'!C5/'中国汇率&期货（vol）'!C5 | D5: ='中国汇率&期货（change）'!D5/'中国汇率&期货（vol）'!D5 | E5: ='中国汇率&期货（change）'!E5/'中国汇率&期货（vol）'!E5 | F5: ='中国汇率&期货（change）'!F5/'中国汇率&期货（vol）'!F5 | G5: ='中国汇率&期货（change）'!G5/'中国汇率&期货（vol）'!G5 | H5: ='中国汇率&期货（change）'!H5/'中国汇率&期货（vol）'!H5 | I5: ='中国汇率&期货（change）'!I5/'中国汇率&期货（vol）'!I5 | ... BE5: ='中国汇率&期货（change）'!BE5/'中国汇率&期货（vol）'!BE5
B6: ='中国汇率&期货（change）'!B6/'中国汇率&期货（vol）'!B6 | C6: ='中国汇率&期货（change）'!C6/'中国汇率&期货（vol）'!C6 | D6: ='中国汇率&期货（change）'!D6/'中国汇率&期货（vol）'!D6 | E6: ='中国汇率&期货（change）'!E6/'中国汇率&期货（vol）'!E6 | F6: ='中国汇率&期货（change）'!F6/'中国汇率&期货（vol）'!F6 | G6: ='中国汇率&期货（change）'!G6/'中国汇率&期货（vol）'!G6 | H6: ='中国汇率&期货（change）'!H6/'中国汇率&期货（vol）'!H6 | I6: ='中国汇率&期货（change）'!I6/'中国汇率&期货（vol）'!I6 | ... BE6: ='中国汇率&期货（change）'!BE6/'中国汇率&期货（vol）'!BE6
B7: ='中国汇率&期货（change）'!B7/'中国汇率&期货（vol）'!B7 | C7: ='中国汇率&期货（change）'!C7/'中国汇率&期货（vol）'!C7 | D7: ='中国汇率&期货（change）'!D7/'中国汇率&期货（vol）'!D7 | E7: ='中国汇率&期货（change）'!E7/'中国汇率&期货（vol）'!E7 | F7: ='中国汇率&期货（change）'!F7/'中国汇率&期货（vol）'!F7 | G7: ='中国汇率&期货（change）'!G7/'中国汇率&期货（vol）'!G7 | H7: ='中国汇率&期货（change）'!H7/'中国汇率&期货（vol）'!H7 | I7: ='中国汇率&期货（change）'!I7/'中国汇率&期货（vol）'!I7 | ... BE7: ='中国汇率&期货（change）'!BE7/'中国汇率&期货（vol）'!BE7
B8: ='中国汇率&期货（change）'!B8/'中国汇率&期货（vol）'!B8 | C8: ='中国汇率&期货（change）'!C8/'中国汇率&期货（vol）'!C8 | D8: ='中国汇率&期货（change）'!D8/'中国汇率&期货（vol）'!D8 | E8: ='中国汇率&期货（change）'!E8/'中国汇率&期货（vol）'!E8 | F8: ='中国汇率&期货（change）'!F8/'中国汇率&期货（vol）'!F8 | G8: ='中国汇率&期货（change）'!G8/'中国汇率&期货（vol）'!G8 | H8: ='中国汇率&期货（change）'!H8/'中国汇率&期货（vol）'!H8 | I8: ='中国汇率&期货（change）'!I8/'中国汇率&期货（vol）'!I8 | ... BE8: ='中国汇率&期货（change）'!BE8/'中国汇率&期货（vol）'!BE8
B9: ='中国汇率&期货（change）'!B9/'中国汇率&期货（vol）'!B9 | C9: ='中国汇率&期货（change）'!C9/'中国汇率&期货（vol）'!C9 | D9: ='中国汇率&期货（change）'!D9/'中国汇率&期货（vol）'!D9 | E9: ='中国汇率&期货（change）'!E9/'中国汇率&期货（vol）'!E9 | F9: ='中国汇率&期货（change）'!F9/'中国汇率&期货（vol）'!F9 | G9: ='中国汇率&期货（change）'!G9/'中国汇率&期货（vol）'!G9 | H9: ='中国汇率&期货（change）'!H9/'中国汇率&期货（vol）'!H9 | I9: ='中国汇率&期货（change）'!I9/'中国汇率&期货（vol）'!I9 | ... BE9: ='中国汇率&期货（change）'!BE9/'中国汇率&期货（vol）'!BE9
B10: ='中国汇率&期货（change）'!B10/'中国汇率&期货（vol）'!B10 | C10: ='中国汇率&期货（change）'!C10/'中国汇率&期货（vol）'!C10 | D10: ='中国汇率&期货（change）'!D10/'中国汇率&期货（vol）'!D10 | E10: ='中国汇率&期货（change）'!E10/'中国汇率&期货（vol）'!E10 | F10: ='中国汇率&期货（change）'!F10/'中国汇率&期货（vol）'!F10 | G10: ='中国汇率&期货（change）'!G10/'中国汇率&期货（vol）'!G10 | H10: ='中国汇率&期货（change）'!H10/'中国汇率&期货（vol）'!H10 | I10: ='中国汇率&期货（change）'!I10/'中国汇率&期货（vol）'!I10 | ... BE10: ='中国汇率&期货（change）'!BE10/'中国汇率&期货（vol）'!BE10
B11: ='中国汇率&期货（change）'!B11/'中国汇率&期货（vol）'!B11 | C11: ='中国汇率&期货（change）'!C11/'中国汇率&期货（vol）'!C11 | D11: ='中国汇率&期货（change）'!D11/'中国汇率&期货（vol）'!D11 | E11: ='中国汇率&期货（change）'!E11/'中国汇率&期货（vol）'!E11 | F11: ='中国汇率&期货（change）'!F11/'中国汇率&期货（vol）'!F11 | G11: ='中国汇率&期货（change）'!G11/'中国汇率&期货（vol）'!G11 | H11: ='中国汇率&期货（change）'!H11/'中国汇率&期货（vol）'!H11 | I11: ='中国汇率&期货（change）'!I11/'中国汇率&期货（vol）'!I11 | ... BE11: ='中国汇率&期货（change）'!BE11/'中国汇率&期货（vol）'!BE11
B12: ='中国汇率&期货（change）'!B12/'中国汇率&期货（vol）'!B12 | C12: ='中国汇率&期货（change）'!C12/'中国汇率&期货（vol）'!C12 | D12: ='中国汇率&期货（change）'!D12/'中国汇率&期货（vol）'!D12 | E12: ='中国汇率&期货（change）'!E12/'中国汇率&期货（vol）'!E12 | F12: ='中国汇率&期货（change）'!F12/'中国汇率&期货（vol）'!F12 | G12: ='中国汇率&期货（change）'!G12/'中国汇率&期货（vol）'!G12 | H12: ='中国汇率&期货（change）'!H12/'中国汇率&期货（vol）'!H12 | I12: ='中国汇率&期货（change）'!I12/'中国汇率&期货（vol）'!I12 | ... BE12: ='中国汇率&期货（change）'!BE12/'中国汇率&期货（vol）'!BE12
B13: ='中国汇率&期货（change）'!B13/'中国汇率&期货（vol）'!B13 | C13: ='中国汇率&期货（change）'!C13/'中国汇率&期货（vol）'!C13 | D13: ='中国汇率&期货（change）'!D13/'中国汇率&期货（vol）'!D13 | E13: ='中国汇率&期货（change）'!E13/'中国汇率&期货（vol）'!E13 | F13: ='中国汇率&期货（change）'!F13/'中国汇率&期货（vol）'!F13 | G13: ='中国汇率&期货（change）'!G13/'中国汇率&期货（vol）'!G13 | H13: ='中国汇率&期货（change）'!H13/'中国汇率&期货（vol）'!H13 | I13: ='中国汇率&期货（change）'!I13/'中国汇率&期货（vol）'!I13 | ... BE13: ='中国汇率&期货（change）'!BE13/'中国汇率&期货（vol）'!BE13
B14: ='中国汇率&期货（change）'!B14/'中国汇率&期货（vol）'!B14 | C14: ='中国汇率&期货（change）'!C14/'中国汇率&期货（vol）'!C14 | D14: ='中国汇率&期货（change）'!D14/'中国汇率&期货（vol）'!D14 | E14: ='中国汇率&期货（change）'!E14/'中国汇率&期货（vol）'!E14 | F14: ='中国汇率&期货（change）'!F14/'中国汇率&期货（vol）'!F14 | G14: ='中国汇率&期货（change）'!G14/'中国汇率&期货（vol）'!G14 | H14: ='中国汇率&期货（change）'!H14/'中国汇率&期货（vol）'!H14 | I14: ='中国汇率&期货（change）'!I14/'中国汇率&期货（vol）'!I14 | ... BE14: ='中国汇率&期货（change）'!BE14/'中国汇率&期货（vol）'!BE14
B15: ='中国汇率&期货（change）'!B15/'中国汇率&期货（vol）'!B15 | C15: ='中国汇率&期货（change）'!C15/'中国汇率&期货（vol）'!C15 | D15: ='中国汇率&期货（change）'!D15/'中国汇率&期货（vol）'!D15 | E15: ='中国汇率&期货（change）'!E15/'中国汇率&期货（vol）'!E15 | F15: ='中国汇率&期货（change）'!F15/'中国汇率&期货（vol）'!F15 | G15: ='中国汇率&期货（change）'!G15/'中国汇率&期货（vol）'!G15 | H15: ='中国汇率&期货（change）'!H15/'中国汇率&期货（vol）'!H15 | I15: ='中国汇率&期货（change）'!I15/'中国汇率&期货（vol）'!I15 | ... BE15: ='中国汇率&期货（change）'!BE15/'中国汇率&期货（vol）'!BE15
B16: ='中国汇率&期货（change）'!B16/'中国汇率&期货（vol）'!B16 | C16: ='中国汇率&期货（change）'!C16/'中国汇率&期货（vol）'!C16 | D16: ='中国汇率&期货（change）'!D16/'中国汇率&期货（vol）'!D16 | E16: ='中国汇率&期货（change）'!E16/'中国汇率&期货（vol）'!E16 | F16: ='中国汇率&期货（change）'!F16/'中国汇率&期货（vol）'!F16 | G16: ='中国汇率&期货（change）'!G16/'中国汇率&期货（vol）'!G16 | H16: ='中国汇率&期货（change）'!H16/'中国汇率&期货（vol）'!H16 | I16: ='中国汇率&期货（change）'!I16/'中国汇率&期货（vol）'!I16 | ... BE16: ='中国汇率&期货（change）'!BE16/'中国汇率&期货（vol）'!BE16
... B77: ='中国汇率&期货（change）'!B77/'中国汇率&期货（vol）'!B77 | C77: ='中国汇率&期货（change）'!C77/'中国汇率&期货（vol）'!C77 | D77: ='中国汇率&期货（change）'!D77/'中国汇率&期货（vol）'!D77 | E77: ='中国汇率&期货（change）'!E77/'中国汇率&期货（vol）'!E77 | F77: ='中国汇率&期货（change）'!F77/'中国汇率&期货（vol）'!F77 | G77: ='中国汇率&期货（change）'!G77/'中国汇率&期货（vol）'!G77 | H77: ='中国汇率&期货（change）'!H77/'中国汇率&期货（vol）'!H77 | I77: ='中国汇率&期货（change）'!I77/'中国汇率&期货（vol）'!I77 | ... BE77: ='中国汇率&期货（change）'!BE77/'中国汇率&期货（vol）'!BE77

Sheet Sheet6
